Workbook

Sheet README
A1: Pulso · Financial Model
A2: 24 meses · Abr 2026 → Mar 2028 · Pre-seed/Seed
A5: Estructura del modelo
A7: 1. Assumptions — todas las variables que controlás (azul = editable)
A8: 2. Revenue — modelo de ingresos por tier (Starter, Growth, Platform)
A9: 3. Payroll — headcount y costo total mes a mes
A10: 4. P&L — pérdidas y ganancias mensuales
A11: 5. Cash Flow — runway, cash en banco, mes en que se acaba la plata
A13: Cómo correr scenarios
A15: Editá solo las celdas en azul de Assumptions. Todo lo demás se recalcula.
A16: Las celdas con fondo amarillo son los key drivers — empezá por ahí.
A17: Para comparar 3 escenarios (base / optimistic / pessimistic):
... A34: · Cuando levantes la ronda y pases a >$50K MRR, contratá un finance person que arme un modelo de verdad.

Sheet Assumptions
A1: Assumptions
A2: Editá solo las celdas azules. Las amarillas son los drivers que más mueven el modelo.
A4: PRICING
A5: Starter (USD/mo) | B5: 0
A6: Growth (USD/mo) | B6: 890 | C6: Sticker price del tier core
A7: Platform (USD/mo, promedio) | B7: 3000 | C7: Custom; promedio asumido
A9: ACQUISITION — pago neto NUEVOS por mes
A10: Mes 1 | B10: 0
A11: Mes 3 | B11: 1 | C11: Primer cliente pago
A12: Mes 6 | B12: 2
A13: Mes 9 | B13: 3
A14: Mes 12 | B14: 4
A15: Mes 15 | B15: 5
A16: Mes 18 | B16: 6
A17: Mes 21 | B17: 7
A18: Mes 24 | B18: 8
A20: MIX — % de NUEVOS clientes que van a Platform vs Growth
A21: % Platform Y1 | B21: 0.2 | C21: El resto va a Growth
A22: % Platform Y2 | B22: 0.3
A24: RETENTION
A25: Churn mensual % | B25: 0.04 | C25: Bajo es mejor. SaaS B2B sano: 1-2%/mes
A27: COGS
A28: Hosting+infra por cliente activo (USD/mo) | B28: 25 | C28: Supabase + Vercel + monitoring
A29: Soporte por cliente (USD/mo) | B29: 15 | C29: Tiempo founder/CSM
A31: PAYROLL — salarios USD/mes (gross)
A32: Founder | B32: 4500 | C32: Sub-mercado mientras runway corto
A33: Engineer 1 (M5+) | B33: 6000
A34: Engineer 2 (M15+) | B34: 6500
A35: GTM/Founder Associate (M13+) | B35: 5500
A36: Burden cargas sociales % | B36: 0.3 | C36: ARG: aprox; ajustá si LATAM otro país
A38: OPEX
A39: SaaS tools (USD/mo) | B39: 350 | C39: Linear, Notion, Cursor, etc
A40: Legal+Accounting (USD/mo) | B40: 600
A41: Marketing (USD/mo, primeros 6) | B41: 500
A42: Marketing (USD/mo, M7-12) | B42: 1500
A43: Marketing (USD/mo, M13+) | B43: 3000
A44: Coworking/oficina (USD/mo) | B44: 350
A45: Otros (USD/mo) | B45: 250
A47: FUNDING
A48: Cash inicial (USD) | B48: 0 | C48: Antes de la ronda
...

Sheet Revenue
A1: Revenue Model
B3: Abr-26 | C3: May-26 | D3: Jun-26 | E3: Jul-26 | F3: Ago-26 | G3: Sep-26 | H3: Oct-26 | I3: Nov-26 | J3: Dic-26 | K3: Ene-27 | L3: Feb-27 | M3: Mar-27 | N3: Abr-27 | O3: May-27 | P3: Jun-27 | Q3: Jul-27 | R3: Ago-27 | S3: Sep-27 | T3: Oct-27 | U3: Nov-27 | V3: Dic-27 | W3: Ene-28 | X3: Feb-28 | Y3: Mar-28
A4: Mes # | B4: 1 | C4: 2 | D4: 3 | E4: 4 | F4: 5 | G4: 6 | H4: 7 | I4: 8 | J4: 9 | K4: 10 | L4: 11 | M4: 12 | N4: 13 | O4: 14 | P4: 15 | Q4: 16 | R4: 17 | S4: 18 | T4: 19 | U4: 20 | V4: 21 | W4: 22 | X4: 23 | Y4: 24
A5: Nuevos clientes (mes) | B5: =ROUND(Assumptions!B10+(Assumptions!B11-Assumptions!B10)*(1-1)/(2),0) -> 0 | C5: =ROUND(Assumptions!B10+(Assumptions!B11-Assumptions!B10)*(2-1)/(2),0) -> 1 | D5: =ROUND(Assumptions!B10+(Assumptions!B11-Assumptions!B10)*(3-1)/(2),0) -> 1 | E5: =ROUND(Assumptions!B11+(Assumptions!B12-Assumptions!B11)*(4-3)/(3),0) -> 1 | F5: =ROUND(Assumptions!B11+(Assumptions!B12-Assumptions!B11)*(5-3)/(3),0) -> 2 | G5: =ROUND(Assumptions!B11+(Assumptions!B12-Assumptions!B11)*(6-3)/(3),0) -> 2 | H5: =ROUND(Assumptions!B12+(Assumptions!B13-Assumptions!B12)*(7-6)/(3),0) -> 2 | I5: =ROUND(Assumptions!B12+(Assumptions!B13-Assumptions!B12)*(8-6)/(3),0) -> 3 | J5: =ROUND(Assumptions!B12+(Assumptions!B13-Assumptions!B12)*(9-6)/(3),0) -> 3 | K5: =ROUND(Assumptions!B13+(Assumptions!B14-Assumptions!B13)*(10-9)/(3),0) -> 3 | L5: =ROUND(Assumptions!B13+(Assumptions!B14-Assumptions!B13)*(11-9)/(3),0) -> 4 | M5: =ROUND(Assumptions!B13+(Assumptions!B14-Assumptions!B13)*(12-9)/(3),0) -> 4 | N5: =ROUND(Assumptions!B14+(Assumptions!B15-Assumptions!B14)*(13-12)/(3),0) -> 4 | O5: =ROUND(Assumptions!B14+(Assumptions!B15-Assumptions!B14)*(14-12)/(3),0) -> 5 | P5: =ROUND(Assumptions!B14+(Assumptions!B15-Assumptions!B14)*(15-12)/(3),0) -> 5 | Q5: =ROUND(Assumptions!B15+(Assumptions!B16-Assumptions!B15)*(16-15)/(3),0) -> 5 | R5: =ROUND(Assumptions!B15+(Assumptions!B16-Assumptions!B15)*(17-15)/(3),0) -> 6 | S5: =ROUND(Assumptions!B15+(Assumptions!B16-Assumptions!B15)*(18-15)/(3),0) -> 6 | T5: =ROUND(Assumptions!B16+(Assumptions!B17-Assumptions!B16)*(19-18)/(3),0) -> 6 | U5: =ROUND(Assumptions!B16+(Assumptions!B17-Assumptions!B16)*(20-18)/(3),0) -> 7 | V5: =ROUND(Assumptions!B16+(Assumptions!B17-Assumptions!B16)*(21-18)/(3),0) -> 7 | W5: =ROUND(Assumptions!B17+(Assumptions!B18-Assumptions!B17)*(22-21)/(3),0) -> 7 | X5: =ROUND(Assumptions!B17+(Assumptions!B18-Assumptions!B17)*(23-21)/(3),0) -> 8 | Y5: =ROUND(Assumptions!B17+(Assumptions!B18-Assumptions!B17)*(24-21)/(3),0) -> 8
A6: Clientes activos (cumulative) | B6: =B5 -> 0 | C6: =B6*(1-Assumptions!B25)+C5 -> 1 | D6: =C6*(1-Assumptions!B25)+D5 -> 1.96 | E6: =D6*(1-Assumptions!B25)+E5 -> 2.8816 | F6: =E6*(1-Assumptions!B25)+F5 -> 4.766336 | G6: =F6*(1-Assumptions!B25)+G5 -> 6.5756826 | H6: =G6*(1-Assumptions!B25)+H5 -> 8.3126553 | I6: =H6*(1-Assumptions!B25)+I5 -> 10.980149 | J6: =I6*(1-Assumptions!B25)+J5 -> 13.540943 | K6: =J6*(1-Assumptions!B25)+K5 -> 15.999305 | L6: =K6*(1-Assumptions!B25)+L5 -> 19.359333 | M6: =L6*(1-Assumptions!B25)+M5 -> 22.58496 | N6: =M6*(1-Assumptions!B25)+N5 -> 25.681561 | O6: =N6*(1-Assumptions!B25)+O5 -> 29.654299 | P6: =O6*(1-Assumptions!B25)+P5 -> 33.468127 | Q6: =P6*(1-Assumptions!B25)+Q5 -> 37.129402 | R6: =Q6*(1-Assumptions!B25)+R5 -> 41.644226 | S6: =R6*(1-Assumptions!B25)+S5 -> 45.978457 | T6: =S6*(1-Assumptions!B25)+T5 -> 50.139319 | U6: =T6*(1-Assumptions!B25)+U5 -> 55.133746 | V6: =U6*(1-Assumptions!B25)+V5 -> 59.928396 | W6: =V6*(1-Assumptions!B25)+W5 -> 64.53126 | X6: =W6*(1-Assumptions!B25)+X5 -> 69.95001 | Y6: =X6*(1-Assumptions!B25)+Y5 -> 75.152009
A7: % nuevos → Platform | B7: =Assumptions!B21 -> 0.2 | C7: =Assumptions!B21 -> 0.2 | D7: =Assumptions!B21 -> 0.2 | E7: =Assumptions!B21 -> 0.2 | F7: =Assumptions!B21 -> 0.2 | G7: =Assumptions!B21 -> 0.2 | H7: =Assumptions!B21 -> 0.2 | I7: =Assumptions!B21 -> 0.2 | J7: =Assumptions!B21 -> 0.2 | K7: =Assumptions!B21 -> 0.2 | L7: =Assumptions!B21 -> 0.2 | M7: =Assumptions!B21 -> 0.2 | N7: =Assumptions!B22 -> 0.3 | O7: =Assumptions!B22 -> 0.3 | P7: =Assumptions!B22 -> 0.3 | Q7: =Assumptions!B22 -> 0.3 | R7: =Assumptions!B22 -> 0.3 | S7: =Assumptions!B22 -> 0.3 | T7: =Assumptions!B22 -> 0.3 | U7: =Assumptions!B22 -> 0.3 | V7: =Assumptions!B22 -> 0.3 | W7: =Assumptions!B22 -> 0.3 | X7: =Assumptions!B22 -> 0.3 | Y7: =Assumptions!B22 -> 0.3
A8: Clientes Platform activos | B8: =ROUND(B6*B7,0) -> 0 | C8: =ROUND(C6*C7,0) -> 0 | D8: =ROUND(D6*D7,0) -> 0 | E8: =ROUND(E6*E7,0) -> 1 | F8: =ROUND(F6*F7,0) -> 1 | G8: =ROUND(G6*G7,0) -> 1 | H8: =ROUND(H6*H7,0) -> 2 | I8: =ROUND(I6*I7,0) -> 2 | ... Y8: =ROUND(Y6*Y7,0) -> 23
A9: Clientes Growth activos | B9: =B6-B8 -> 0 | C9: =C6-C8 -> 1 | D9: =D6-D8 -> 1.96 | E9: =E6-E8 -> 1.8816 | F9: =F6-F8 -> 3.766336 | G9: =G6-G8 -> 5.5756826 | H9: =H6-H8 -> 6.3126553 | I9: =I6-I8 -> 8.980149 | ... Y9: =Y6-Y8 -> 52.152009
A11: MRR Growth (USD) | B11: =B9*Assumptions!B6 -> 0 | C11: =C9*Assumptions!B6 -> 890 | D11: =D9*Assumptions!B6 -> 1744.4 | E11: =E9*Assumptions!B6 -> 1674.624 | F11: =F9*Assumptions!B6 -> 3352.039 | G11: =G9*Assumptions!B6 -> 4962.3575 | H11: =H9*Assumptions!B6 -> 5618.2632 | I11: =I9*Assumptions!B6 -> 7992.3327 | J11: =J9*Assumptions!B6 -> 9381.4393 | K11: =K9*Assumptions!B6 -> 11569.382 | L11: =L9*Assumptions!B6 -> 13669.807 | M11: =M9*Assumptions!B6 -> 15650.614 | N11: =N9*Assumptions!B6 -> 15736.59 | O11: =O9*Assumptions!B6 -> 18382.326 | P11: =P9*Assumptions!B6 -> 20886.633 | Q11: =Q9*Assumptions!B6 -> 23255.168 | R11: =R9*Assumptions!B6 -> 26383.361 | S11: =S9*Assumptions!B6 -> 28460.827 | T11: =T9*Assumptions!B6 -> 31273.994 | U11: =U9*Assumptions!B6 -> 33939.034 | V11: =V9*Assumptions!B6 -> 37316.272 | W11: =W9*Assumptions!B6 -> 40522.822 | X11: =X9*Assumptions!B6 -> 43565.509 | Y11: =Y9*Assumptions!B6 -> 46415.288
A12: MRR Platform (USD) | B12: =B8*Assumptions!B7 -> 0 | C12: =C8*Assumptions!B7 -> 0 | D12: =D8*Assumptions!B7 -> 0 | E12: =E8*Assumptions!B7 -> 3000 | F12: =F8*Assumptions!B7 -> 3000 | G12: =G8*Assumptions!B7 -> 3000 | H12: =H8*Assumptions!B7 -> 6000 | I12: =I8*Assumptions!B7 -> 6000 | J12: =J8*Assumptions!B7 -> 9000 | K12: =K8*Assumptions!B7 -> 9000 | L12: =L8*Assumptions!B7 -> 12000 | M12: =M8*Assumptions!B7 -> 15000 | N12: =N8*Assumptions!B7 -> 24000 | O12: =O8*Assumptions!B7 -> 27000 | P12: =P8*Assumptions!B7 -> 30000 | Q12: =Q8*Assumptions!B7 -> 33000 | R12: =R8*Assumptions!B7 -> 36000 | S12: =S8*Assumptions!B7 -> 42000 | T12: =T8*Assumptions!B7 -> 45000 | U12: =U8*Assumptions!B7 -> 51000 | V12: =V8*Assumptions!B7 -> 54000 | W12: =W8*Assumptions!B7 -> 57000 | X12: =X8*Assumptions!B7 -> 63000 | Y12: =Y8*Assumptions!B7 -> 69000
A13: MRR Total | B13: =B11+B12 -> 0 | C13: =C11+C12 -> 890 | D13: =D11+D12 -> 1744.4 | E13: =E11+E12 -> 4674.624 | F13: =F11+F12 -> 6352.039 | G13: =G11+G12 -> 7962.3575 | H13: =H11+H12 -> 11618.263 | I13: =I11+I12 -> 13992.333 | ... Y13: =Y11+Y12 -> 115415.29
A14: ARR (annualized) | B14: =B13*12 -> 0 | C14: =C13*12 -> 10680 | D14: =D13*12 -> 20932.8 | E14: =E13*12 -> 56095.488 | F14: =F13*12 -> 76224.468 | G14: =G13*12 -> 95548.29 | H14: =H13*12 -> 139419.16 | I14: =I13*12 -> 167907.99 | ... Y14: =Y13*12 -> 1384983.5
A16: Revenue mensual | B16: =B13 -> 0 | C16: =C13 -> 890 | D16: =D13 -> 1744.4 | E16: =E13 -> 4674.624 | F16: =F13 -> 6352.039 | G16: =G13 -> 7962.3575 | H16: =H13 -> 11618.263 | I16: =I13 -> 13992.333 | ... Y16: =Y13 -> 115415.29

Sheet Payroll
A1: Payroll & Headcount
B3: Abr-26 | C3: May-26 | D3: Jun-26 | E3: Jul-26 | F3: Ago-26 | G3: Sep-26 | H3: Oct-26 | I3: Nov-26 | J3: Dic-26 | K3: Ene-27 | L3: Feb-27 | M3: Mar-27 | N3: Abr-27 | O3: May-27 | P3: Jun-27 | Q3: Jul-27 | R3: Ago-27 | S3: Sep-27 | T3: Oct-27 | U3: Nov-27 | V3: Dic-27 | W3: Ene-28 | X3: Feb-28 | Y3: Mar-28
A5: Founder | B5: =Assumptions!B32*(1+Assumptions!B36) -> 5850 | C5: =Assumptions!B32*(1+Assumptions!B36) -> 5850 | D5: =Assumptions!B32*(1+Assumptions!B36) -> 5850 | E5: =Assumptions!B32*(1+Assumptions!B36) -> 5850 | F5: =Assumptions!B32*(1+Assumptions!B36) -> 5850 | G5: =Assumptions!B32*(1+Assumptions!B36) -> 5850 | H5: =Assumptions!B32*(1+Assumptions!B36) -> 5850 | I5: =Assumptions!B32*(1+Assumptions!B36) -> 5850 | J5: =Assumptions!B32*(1+Assumptions!B36) -> 5850 | K5: =Assumptions!B32*(1+Assumptions!B36) -> 5850 | L5: =Assumptions!B32*(1+Assumptions!B36) -> 5850 | M5: =Assumptions!B32*(1+Assumptions!B36) -> 5850 | N5: =Assumptions!B32*(1+Assumptions!B36) -> 5850 | O5: =Assumptions!B32*(1+Assumptions!B36) -> 5850 | P5: =Assumptions!B32*(1+Assumptions!B36) -> 5850 | Q5: =Assumptions!B32*(1+Assumptions!B36) -> 5850 | R5: =Assumptions!B32*(1+Assumptions!B36) -> 5850 | S5: =Assumptions!B32*(1+Assumptions!B36) -> 5850 | T5: =Assumptions!B32*(1+Assumptions!B36) -> 5850 | U5: =Assumptions!B32*(1+Assumptions!B36) -> 5850 | V5: =Assumptions!B32*(1+Assumptions!B36) -> 5850 | W5: =Assumptions!B32*(1+Assumptions!B36) -> 5850 | X5: =Assumptions!B32*(1+Assumptions!B36) -> 5850 | Y5: =Assumptions!B32*(1+Assumptions!B36) -> 5850
A6: Engineer 1 | B6: =0 -> 0 | C6: =0 -> 0 | D6: =0 -> 0 | E6: =0 -> 0 | F6: =Assumptions!B33*(1+Assumptions!B36) -> 7800 | G6: =Assumptions!B33*(1+Assumptions!B36) -> 7800 | H6: =Assumptions!B33*(1+Assumptions!B36) -> 7800 | I6: =Assumptions!B33*(1+Assumptions!B36) -> 7800 | J6: =Assumptions!B33*(1+Assumptions!B36) -> 7800 | K6: =Assumptions!B33*(1+Assumptions!B36) -> 7800 | L6: =Assumptions!B33*(1+Assumptions!B36) -> 7800 | M6: =Assumptions!B33*(1+Assumptions!B36) -> 7800 | N6: =Assumptions!B33*(1+Assumptions!B36) -> 7800 | O6: =Assumptions!B33*(1+Assumptions!B36) -> 7800 | P6: =Assumptions!B33*(1+Assumptions!B36) -> 7800 | Q6: =Assumptions!B33*(1+Assumptions!B36) -> 7800 | R6: =Assumptions!B33*(1+Assumptions!B36) -> 7800 | S6: =Assumptions!B33*(1+Assumptions!B36) -> 7800 | T6: =Assumptions!B33*(1+Assumptions!B36) -> 7800 | U6: =Assumptions!B33*(1+Assumptions!B36) -> 7800 | V6: =Assumptions!B33*(1+Assumptions!B36) -> 7800 | W6: =Assumptions!B33*(1+Assumptions!B36) -> 7800 | X6: =Assumptions!B33*(1+Assumptions!B36) -> 7800 | Y6: =Assumptions!B33*(1+Assumptions!B36) -> 7800
A7: GTM | B7: =0 -> 0 | C7: =0 -> 0 | D7: =0 -> 0 | E7: =0 -> 0 | F7: =0 -> 0 | G7: =0 -> 0 | H7: =0 -> 0 | I7: =0 -> 0 | ... M7: =0 -> 0 | N7: =Assumptions!B35*(1+Assumptions!B36) -> 7150 | O7: =Assumptions!B35*(1+Assumptions!B36) -> 7150 | P7: =Assumptions!B35*(1+Assumptions!B36) -> 7150 | Q7: =Assumptions!B35*(1+Assumptions!B36) -> 7150 | R7: =Assumptions!B35*(1+Assumptions!B36) -> 7150 | S7: =Assumptions!B35*(1+Assumptions!B36) -> 7150 | T7: =Assumptions!B35*(1+Assumptions!B36) -> 7150 | U7: =Assumptions!B35*(1+Assumptions!B36) -> 7150 | V7: =Assumptions!B35*(1+Assumptions!B36) -> 7150 | W7: =Assumptions!B35*(1+Assumptions!B36) -> 7150 | X7: =Assumptions!B35*(1+Assumptions!B36) -> 7150 | Y7: =Assumptions!B35*(1+Assumptions!B36) -> 7150
A8: Engineer 2 | B8: =0 -> 0 | C8: =0 -> 0 | D8: =0 -> 0 | E8: =0 -> 0 | F8: =0 -> 0 | G8: =0 -> 0 | H8: =0 -> 0 | I8: =0 -> 0 | ... O8: =0 -> 0 | P8: =Assumptions!B34*(1+Assumptions!B36) -> 8450 | Q8: =Assumptions!B34*(1+Assumptions!B36) -> 8450 | R8: =Assumptions!B34*(1+Assumptions!B36) -> 8450 | S8: =Assumptions!B34*(1+Assumptions!B36) -> 8450 | T8: =Assumptions!B34*(1+Assumptions!B36) -> 8450 | U8: =Assumptions!B34*(1+Assumptions!B36) -> 8450 | V8: =Assumptions!B34*(1+Assumptions!B36) -> 8450 | W8: =Assumptions!B34*(1+Assumptions!B36) -> 8450 | X8: =Assumptions!B34*(1+Assumptions!B36) -> 8450 | Y8: =Assumptions!B34*(1+Assumptions!B36) -> 8450
A10: Total Payroll | B10: =SUM(B5:B8) -> 5850 | C10: =SUM(C5:C8) -> 5850 | D10: =SUM(D5:D8) -> 5850 | E10: =SUM(E5:E8) -> 5850 | F10: =SUM(F5:F8) -> 13650 | G10: =SUM(G5:G8) -> 13650 | H10: =SUM(H5:H8) -> 13650 | I10: =SUM(I5:I8) -> 13650 | ... Y10: =SUM(Y5:Y8) -> 29250
A12: Headcount FTE | B12: 1 | C12: 1 | D12: 1 | E12: 1 | F12: 2 | G12: 2 | H12: 2 | I12: 2 | J12: 2 | K12: 2 | L12: 2 | M12: 2 | N12: 3 | O12: 3 | P12: 4 | Q12: 4 | R12: 4 | S12: 4 | T12: 4 | U12: 4 | V12: 4 | W12: 4 | X12: 4 | Y12: 4

Sheet P&L
A1: P&L mensual
A3: USD | B3: Abr-26 | C3: May-26 | D3: Jun-26 | E3: Jul-26 | F3: Ago-26 | G3: Sep-26 | H3: Oct-26 | I3: Nov-26 | J3: Dic-26 | K3: Ene-27 | L3: Feb-27 | M3: Mar-27 | N3: Abr-27 | O3: May-27 | P3: Jun-27 | Q3: Jul-27 | R3: Ago-27 | S3: Sep-27 | T3: Oct-27 | U3: Nov-27 | V3: Dic-27 | W3: Ene-28 | X3: Feb-28 | Y3: Mar-28
A5: Revenue | B5: =Revenue!B16 -> 0 | C5: =Revenue!C16 -> 890 | D5: =Revenue!D16 -> 1744.4 | E5: =Revenue!E16 -> 4674.624 | F5: =Revenue!F16 -> 6352.039 | G5: =Revenue!G16 -> 7962.3575 | H5: =Revenue!H16 -> 11618.263 | I5: =Revenue!I16 -> 13992.333 | ... Y5: =Revenue!Y16 -> 115415.29
A7: COGS | B7: =-(Revenue!B6*(Assumptions!B28+Assumptions!B29)) -> 0 | C7: =-(Revenue!C6*(Assumptions!B28+Assumptions!B29)) -> -40 | D7: =-(Revenue!D6*(Assumptions!B28+Assumptions!B29)) -> -78.4 | E7: =-(Revenue!E6*(Assumptions!B28+Assumptions!B29)) -> -115.264 | F7: =-(Revenue!F6*(Assumptions!B28+Assumptions!B29)) -> -190.65344 | G7: =-(Revenue!G6*(Assumptions!B28+Assumptions!B29)) -> -263.0273 | H7: =-(Revenue!H6*(Assumptions!B28+Assumptions!B29)) -> -332.50621 | I7: =-(Revenue!I6*(Assumptions!B28+Assumptions!B29)) -> -439.20596 | J7: =-(Revenue!J6*(Assumptions!B28+Assumptions!B29)) -> -541.63772 | K7: =-(Revenue!K6*(Assumptions!B28+Assumptions!B29)) -> -639.97221 | L7: =-(Revenue!L6*(Assumptions!B28+Assumptions!B29)) -> -774.37333 | M7: =-(Revenue!M6*(Assumptions!B28+Assumptions!B29)) -> -903.39839 | N7: =-(Revenue!N6*(Assumptions!B28+Assumptions!B29)) -> -1027.2625 | O7: =-(Revenue!O6*(Assumptions!B28+Assumptions!B29)) -> -1186.172 | P7: =-(Revenue!P6*(Assumptions!B28+Assumptions!B29)) -> -1338.7251 | Q7: =-(Revenue!Q6*(Assumptions!B28+Assumptions!B29)) -> -1485.1761 | R7: =-(Revenue!R6*(Assumptions!B28+Assumptions!B29)) -> -1665.769 | S7: =-(Revenue!S6*(Assumptions!B28+Assumptions!B29)) -> -1839.1383 | T7: =-(Revenue!T6*(Assumptions!B28+Assumptions!B29)) -> -2005.5727 | U7: =-(Revenue!U6*(Assumptions!B28+Assumptions!B29)) -> -2205.3498 | V7: =-(Revenue!V6*(Assumptions!B28+Assumptions!B29)) -> -2397.1358 | W7: =-(Revenue!W6*(Assumptions!B28+Assumptions!B29)) -> -2581.2504 | X7: =-(Revenue!X6*(Assumptions!B28+Assumptions!B29)) -> -2798.0004 | Y7: =-(Revenue!Y6*(Assumptions!B28+Assumptions!B29)) -> -3006.0804
A8: Gross Profit | B8: =B5+B7 -> 0 | C8: =C5+C7 -> 850 | D8: =D5+D7 -> 1666 | E8: =E5+E7 -> 4559.36 | F8: =F5+F7 -> 6161.3856 | G8: =G5+G7 -> 7699.3302 | H8: =H5+H7 -> 11285.757 | I8: =I5+I7 -> 13553.127 | ... Y8: =Y5+Y7 -> 112409.21
A9: Gross Margin % | B9: =IFERROR(B8/B5,0) -> 0 | C9: =IFERROR(C8/C5,0) -> 0.95505618 | D9: =IFERROR(D8/D5,0) -> 0.95505618 | E9: =IFERROR(E8/E5,0) -> 0.97534262 | F9: =IFERROR(F8/F5,0) -> 0.96998547 | G9: =IFERROR(G8/G5,0) -> 0.96696615 | H9: =IFERROR(H8/H5,0) -> 0.97138073 | I9: =IFERROR(I8/I5,0) -> 0.96861095 | ... Y9: =IFERROR(Y8/Y5,0) -> 0.97395423
A11: OPEX
A12: Payroll (incl. burden) | B12: =-Payroll!B10 -> -5850 | C12: =-Payroll!C10 -> -5850 | D12: =-Payroll!D10 -> -5850 | E12: =-Payroll!E10 -> -5850 | F12: =-Payroll!F10 -> -13650 | G12: =-Payroll!G10 -> -13650 | H12: =-Payroll!H10 -> -13650 | I12: =-Payroll!I10 -> -13650 | ... Y12: =-Payroll!Y10 -> -29250
A13: SaaS tools | B13: =-Assumptions!B39 -> -350 | C13: =-Assumptions!B39 -> -350 | D13: =-Assumptions!B39 -> -350 | E13: =-Assumptions!B39 -> -350 | F13: =-Assumptions!B39 -> -350 | G13: =-Assumptions!B39 -> -350 | H13: =-Assumptions!B39 -> -350 | I13: =-Assumptions!B39 -> -350 | J13: =-Assumptions!B39 -> -350 | K13: =-Assumptions!B39 -> -350 | L13: =-Assumptions!B39 -> -350 | M13: =-Assumptions!B39 -> -350 | N13: =-Assumptions!B39 -> -350 | O13: =-Assumptions!B39 -> -350 | P13: =-Assumptions!B39 -> -350 | Q13: =-Assumptions!B39 -> -350 | R13: =-Assumptions!B39 -> -350 | S13: =-Assumptions!B39 -> -350 | T13: =-Assumptions!B39 -> -350 | U13: =-Assumptions!B39 -> -350 | V13: =-Assumptions!B39 -> -350 | W13: =-Assumptions!B39 -> -350 | X13: =-Assumptions!B39 -> -350 | Y13: =-Assumptions!B39 -> -350
A14: Legal+Accounting | B14: =-Assumptions!B40 -> -600 | C14: =-Assumptions!B40 -> -600 | D14: =-Assumptions!B40 -> -600 | E14: =-Assumptions!B40 -> -600 | F14: =-Assumptions!B40 -> -600 | G14: =-Assumptions!B40 -> -600 | H14: =-Assumptions!B40 -> -600 | I14: =-Assumptions!B40 -> -600 | J14: =-Assumptions!B40 -> -600 | K14: =-Assumptions!B40 -> -600 | L14: =-Assumptions!B40 -> -600 | M14: =-Assumptions!B40 -> -600 | N14: =-Assumptions!B40 -> -600 | O14: =-Assumptions!B40 -> -600 | P14: =-Assumptions!B40 -> -600 | Q14: =-Assumptions!B40 -> -600 | R14: =-Assumptions!B40 -> -600 | S14: =-Assumptions!B40 -> -600 | T14: =-Assumptions!B40 -> -600 | U14: =-Assumptions!B40 -> -600 | V14: =-Assumptions!B40 -> -600 | W14: =-Assumptions!B40 -> -600 | X14: =-Assumptions!B40 -> -600 | Y14: =-Assumptions!B40 -> -600
A15: Marketing | B15: =-Assumptions!B41 -> -500 | C15: =-Assumptions!B41 -> -500 | D15: =-Assumptions!B41 -> -500 | E15: =-Assumptions!B41 -> -500 | F15: =-Assumptions!B41 -> -500 | G15: =-Assumptions!B41 -> -500 | H15: =-Assumptions!B42 -> -1500 | I15: =-Assumptions!B42 -> -1500 | J15: =-Assumptions!B42 -> -1500 | K15: =-Assumptions!B42 -> -1500 | L15: =-Assumptions!B42 -> -1500 | M15: =-Assumptions!B42 -> -1500 | N15: =-Assumptions!B43 -> -3000 | O15: =-Assumptions!B43 -> -3000 | P15: =-Assumptions!B43 -> -3000 | Q15: =-Assumptions!B43 -> -3000 | R15: =-Assumptions!B43 -> -3000 | S15: =-Assumptions!B43 -> -3000 | T15: =-Assumptions!B43 -> -3000 | U15: =-Assumptions!B43 -> -3000 | V15: =-Assumptions!B43 -> -3000 | W15: =-Assumptions!B43 -> -3000 | X15: =-Assumptions!B43 -> -3000 | Y15: =-Assumptions!B43 -> -3000
A16: Coworking/oficina | B16: =-Assumptions!B44 -> -350 | C16: =-Assumptions!B44 -> -350 | D16: =-Assumptions!B44 -> -350 | E16: =-Assumptions!B44 -> -350 | F16: =-Assumptions!B44 -> -350 | G16: =-Assumptions!B44 -> -350 | H16: =-Assumptions!B44 -> -350 | I16: =-Assumptions!B44 -> -350 | J16: =-Assumptions!B44 -> -350 | K16: =-Assumptions!B44 -> -350 | L16: =-Assumptions!B44 -> -350 | M16: =-Assumptions!B44 -> -350 | N16: =-Assumptions!B44 -> -350 | O16: =-Assumptions!B44 -> -350 | P16: =-Assumptions!B44 -> -350 | Q16: =-Assumptions!B44 -> -350 | R16: =-Assumptions!B44 -> -350 | S16: =-Assumptions!B44 -> -350 | T16: =-Assumptions!B44 -> -350 | U16: =-Assumptions!B44 -> -350 | V16: =-Assumptions!B44 -> -350 | W16: =-Assumptions!B44 -> -350 | X16: =-Assumptions!B44 -> -350 | Y16: =-Assumptions!B44 -> -350
A17: Otros | B17: =-Assumptions!B45 -> -250 | C17: =-Assumptions!B45 -> -250 | D17: =-Assumptions!B45 -> -250 | E17: =-Assumptions!B45 -> -250 | F17: =-Assumptions!B45 -> -250 | G17: =-Assumptions!B45 -> -250 | H17: =-Assumptions!B45 -> -250 | I17: =-Assumptions!B45 -> -250 | J17: =-Assumptions!B45 -> -250 | K17: =-Assumptions!B45 -> -250 | L17: =-Assumptions!B45 -> -250 | M17: =-Assumptions!B45 -> -250 | N17: =-Assumptions!B45 -> -250 | O17: =-Assumptions!B45 -> -250 | P17: =-Assumptions!B45 -> -250 | Q17: =-Assumptions!B45 -> -250 | R17: =-Assumptions!B45 -> -250 | S17: =-Assumptions!B45 -> -250 | T17: =-Assumptions!B45 -> -250 | U17: =-Assumptions!B45 -> -250 | V17: =-Assumptions!B45 -> -250 | W17: =-Assumptions!B45 -> -250 | X17: =-Assumptions!B45 -> -250 | Y17: =-Assumptions!B45 -> -250
A18: Total OPEX | B18: =SUM(B12:B17) -> -7900 | C18: =SUM(C12:C17) -> -7900 | D18: =SUM(D12:D17) -> -7900 | E18: =SUM(E12:E17) -> -7900 | F18: =SUM(F12:F17) -> -15700 | G18: =SUM(G12:G17) -> -15700 | H18: =SUM(H12:H17) -> -16700 | I18: =SUM(I12:I17) -> -16700 | ... Y18: =SUM(Y12:Y17) -> -33800
A20: EBITDA | B20: =B8+B18 -> -7900 | C20: =C8+C18 -> -7050 | D20: =D8+D18 -> -6234 | E20: =E8+E18 -> -3340.64 | F20: =F8+F18 -> -9538.6144 | G20: =G8+G18 -> -8000.6698 | H20: =H8+H18 -> -5414.243 | I20: =I8+I18 -> -3146.8733 | ... Y20: =Y8+Y18 -> 78609.208

Sheet Cash Flow
A1: Cash Flow & Runway
A3: USD | B3: Abr-26 | C3: May-26 | D3: Jun-26 | E3: Jul-26 | F3: Ago-26 | G3: Sep-26 | H3: Oct-26 | I3: Nov-26 | J3: Dic-26 | K3: Ene-27 | L3: Feb-27 | M3: Mar-27 | N3: Abr-27 | O3: May-27 | P3: Jun-27 | Q3: Jul-27 | R3: Ago-27 | S3: Sep-27 | T3: Oct-27 | U3: Nov-27 | V3: Dic-27 | W3: Ene-28 | X3: Feb-28 | Y3: Mar-28 | AA3: Resumen 24M
A5: EBITDA | B5: ='P&L'!B20 -> -7900 | C5: ='P&L'!C20 -> -7050 | D5: ='P&L'!D20 -> -6234 | E5: ='P&L'!E20 -> -3340.64 | F5: ='P&L'!F20 -> -9538.6144 | G5: ='P&L'!G20 -> -8000.6698 | H5: ='P&L'!H20 -> -5414.243 | I5: ='P&L'!I20 -> -3146.8733 | ... Y5: ='P&L'!Y20 -> 78609.208 | AA5: Total revenue | AB5: =SUM('P&L'!B5:Y5) -> 1039643.1
A6: Funding (ronda) | B6: =IF(1=Assumptions!B50,Assumptions!B49,0) -> 500000 | C6: =IF(2=Assumptions!B50,Assumptions!B49,0) -> 0 | D6: =IF(3=Assumptions!B50,Assumptions!B49,0) -> 0 | E6: =IF(4=Assumptions!B50,Assumptions!B49,0) -> 0 | F6: =IF(5=Assumptions!B50,Assumptions!B49,0) -> 0 | G6: =IF(6=Assumptions!B50,Assumptions!B49,0) -> 0 | H6: =IF(7=Assumptions!B50,Assumptions!B49,0) -> 0 | I6: =IF(8=Assumptions!B50,Assumptions!B49,0) -> 0 | J6: =IF(9=Assumptions!B50,Assumptions!B49,0) -> 0 | K6: =IF(10=Assumptions!B50,Assumptions!B49,0) -> 0 | L6: =IF(11=Assumptions!B50,Assumptions!B49,0) -> 0 | M6: =IF(12=Assumptions!B50,Assumptions!B49,0) -> 0 | N6: =IF(13=Assumptions!B50,Assumptions!B49,0) -> 0 | O6: =IF(14=Assumptions!B50,Assumptions!B49,0) -> 0 | P6: =IF(15=Assumptions!B50,Assumptions!B49,0) -> 0 | Q6: =IF(16=Assumptions!B50,Assumptions!B49,0) -> 0 | R6: =IF(17=Assumptions!B50,Assumptions!B49,0) -> 0 | S6: =IF(18=Assumptions!B50,Assumptions!B49,0) -> 0 | T6: =IF(19=Assumptions!B50,Assumptions!B49,0) -> 0 | U6: =IF(20=Assumptions!B50,Assumptions!B49,0) -> 0 | V6: =IF(21=Assumptions!B50,Assumptions!B49,0) -> 0 | W6: =IF(22=Assumptions!B50,Assumptions!B49,0) -> 0 | X6: =IF(23=Assumptions!B50,Assumptions!B49,0) -> 0 | Y6: =IF(24=Assumptions!B50,Assumptions!B49,0) -> 0 | AA6: Total burn | AB6: =SUM(B12:Y12) -> 50625.041
A7: Cambio en cash | B7: =B5+B6 -> 492100 | C7: =C5+C6 -> -7050 | D7: =D5+D6 -> -6234 | E7: =E5+E6 -> -3340.64 | F7: =F5+F6 -> -9538.6144 | G7: =G5+G6 -> -8000.6698 | H7: =H5+H6 -> -5414.243 | I7: =I5+I6 -> -3146.8733 | ... Y7: =Y5+Y6 -> 78609.208 | AA7: Cash final M24 | AB7: =Y10 -> 959889.01
AA8: ARR a M24 | AB8: =Revenue!Y14 -> 1384983.5
A9: Cash inicio mes | B9: =Assumptions!B48 -> 0 | C9: =B10 -> 492100 | D9: =C10 -> 485050 | E9: =D10 -> 478816 | F9: =E10 -> 475475.36 | G9: =F10 -> 465936.75 | H9: =G10 -> 457936.08 | I9: =H10 -> 452521.83 | J9: =I10 -> 449374.96 | ... Y9: =X10 -> 881279.8 | AA9: Mes break-even (EBITDA>0) | AB9: =IFERROR(MATCH(TRUE(),B5:Y5>0,0),"No alcanzado") -> 9
A10: Cash fin de mes | B10: =B9+B7 -> 492100 | C10: =C9+C7 -> 485050 | D10: =D9+D7 -> 478816 | E10: =E9+E7 -> 475475.36 | F10: =F9+F7 -> 465936.75 | G10: =G9+G7 -> 457936.08 | H10: =H9+H7 -> 452521.83 | I10: =I9+I7 -> 449374.96 | ... Y10: =Y9+Y7 -> 959889.01
A12: Burn mensual | B12: =IF(B5<0,-B5,0) -> 7900 | C12: =IF(C5<0,-C5,0) -> 7050 | D12: =IF(D5<0,-D5,0) -> 6234 | E12: =IF(E5<0,-E5,0) -> 3340.64 | F12: =IF(F5<0,-F5,0) -> 9538.6144 | G12: =IF(G5<0,-G5,0) -> 8000.6698 | H12: =IF(H5<0,-H5,0) -> 5414.243 | I12: =IF(I5<0,-I5,0) -> 3146.8733 | ... Y12: =IF(Y5<0,-Y5,0) -> 0
A13: Burn promedio L3M | B13: =AVERAGE($B12:B12) -> 7900 | C13: =AVERAGE($B12:C12) -> 7475 | D13: =AVERAGE(B12:D12) -> 7061.3333 | E13: =AVERAGE(C12:E12) -> 5541.5467 | F13: =AVERAGE(D12:F12) -> 6371.0848 | G13: =AVERAGE(E12:G12) -> 6959.9747 | H13: =AVERAGE(F12:H12) -> 7651.1758 | I13: =AVERAGE(G12:I12) -> 5520.5954 | J13: =AVERAGE(H12:J12) -> 2853.7054 | K13: =AVERAGE(I12:K12) -> 1048.9578 | ... Y13: =AVERAGE(W12:Y12) -> 0
A14: Runway (meses) | B14: =IF(B13>0,B10/B13,">24") -> 62.291139 | C14: =IF(C13>0,C10/C13,">24") -> 64.889632 | D14: =IF(D13>0,D10/D13,">24") -> 67.808157 | E14: =IF(E13>0,E10/E13,">24") -> 85.801923 | F14: =IF(F13>0,F10/F13,">24") -> 73.133032 | G14: =IF(G13>0,G10/G13,">24") -> 65.795652 | H14: =IF(H13>0,H10/H13,">24") -> 59.144091 | I14: =IF(I13>0,I10/I13,">24") -> 81.399727 | ... Y14: =IF(Y13>0,Y10/Y13,">24") -> >24
